Workbook

Sheet 단가설정
A1: BNB 리뉴얼 내부 견적서 입력값
A3: 입력 안내
A4: 1. 노란색 셀만 수정하면 됩니다.
A5: 2. 직군 단가를 수정하면 견적입력 시트의 연동 항목 금액이 비례 반영됩니다.
A6: 3. 견적입력 시트에서 포함(Y/N), 기준금액, 수동금액을 바꾸면 요약이 자동 갱신됩니다.
A8: VAT | B8: 0.1
A10: 직군 | B10: LOW | C10: MID | D10: HIGH
A11: UX 디자이너 | B11: 350000 | C11: 450000 | D11: 600000
A12: UI 디자이너 | B12: 300000 | C12: 400000 | D12: 550000
A13: 프론트엔드 개발 | B13: 400000 | C13: 500000 | D13: 650000
A14: 백엔드/CMS 개발 | B14: 400000 | C14: 500000 | D14: 650000
A15: PM | B15: 300000 | C15: 400000 | D15: 500000
A16: QA | B16: 250000 | C16: 300000 | D16: 400000

Sheet 견적입력
A1: BNB 리뉴얼 내부 견적 입력
A2: 노란색 셀은 입력용, 초록색 셀은 자동 계산입니다. 포함 열에서 Y를 선택한 항목만 합계에 반영됩니다.
A3: 포함 | B3: 대분류 | C3: 세부구분 | D3: 항목 | E3: 연동직군 | F3: 공수(일) | G3: LOW 기준금액 | H3: MID 기준금액 | I3: HIGH 기준금액 | J3: LOW 수동금액 | K3: MID 수동금액 | L3: HIGH 수동금액 | M3: LOW 반영금액 | N3: MID 반영금액 | O3: HIGH 반영금액 | P3: 비고 | Q3: 기준 LOW단가 | R3: 기준 MID단가 | S3: 기준 HIGH단가
A4: Y | B4: a) 마스터 템플릿 | C4: 디자인 | D4: 디자인 시스템 (색상/타이포/간격/그리드) | E4: UX 디자이너 | F4: 5 | G4: 1500000 | H4: 2000000 | I4: 3000000 | M4: =IF($A4<>"Y",0,IF($J4<>"",$J4,IF($Q4="",$G4,ROUND($G4*(IF($E4="","",IFERROR(INDEX(단가설정!$B$11:$B$16,MATCH($E4,단가설정!$A$11:$A$16,0)),""))/$Q4),0)))) | N4: =IF($A4<>"Y",0,IF($K4<>"",$K4,IF($R4="",$H4,ROUND($H4*(IF($E4="","",IFERROR(INDEX(단가설정!$C$11:$C$16,MATCH($E4,단가설정!$A$11:$A$16,0)),""))/$R4),0)))) | O4: =IF($A4<>"Y",0,IF($L4<>"",$L4,IF($S4="",$I4,ROUND($I4*(IF($E4="","",IFERROR(INDEX(단가설정!$D$11:$D$16,MATCH($E4,단가설정!$A$11:$A$16,0)),""))/$S4),0)))) | Q4: =IF($E4="","",IFERROR(INDEX(단가설정!$B$11:$B$16,MATCH($E4,단가설정!$A$11:$A$16,0)),"")) | R4: =IF($E4="","",IFERROR(INDEX(단가설정!$C$11:$C$16,MATCH($E4,단가설정!$A$11:$A$16,0)),"")) | S4: =IF($E4="","",IFERROR(INDEX(단가설정!$D$11:$D$16,MATCH($E4,단가설정!$A$11:$A$16,0)),""))
A5: Y | B5: a) 마스터 템플릿 | C5: 디자인 | D5: 메인페이지 디자인 (PC+Mobile) | E5: UX 디자이너 | F5: 5 | G5: 1500000 | H5: 2250000 | I5: 3000000 | M5: =IF($A5<>"Y",0,IF($J5<>"",$J5,IF($Q5="",$G5,ROUND($G5*(IF($E5="","",IFERROR(INDEX(단가설정!$B$11:$B$16,MATCH($E5,단가설정!$A$11:$A$16,0)),""))/$Q5),0)))) | N5: =IF($A5<>"Y",0,IF($K5<>"",$K5,IF($R5="",$H5,ROUND($H5*(IF($E5="","",IFERROR(INDEX(단가설정!$C$11:$C$16,MATCH($E5,단가설정!$A$11:$A$16,0)),""))/$R5),0)))) | O5: =IF($A5<>"Y",0,IF($L5<>"",$L5,IF($S5="",$I5,ROUND($I5*(IF($E5="","",IFERROR(INDEX(단가설정!$D$11:$D$16,MATCH($E5,단가설정!$A$11:$A$16,0)),""))/$S5),0)))) | Q5: =IF($E5="","",IFERROR(INDEX(단가설정!$B$11:$B$16,MATCH($E5,단가설정!$A$11:$A$16,0)),"")) | R5: =IF($E5="","",IFERROR(INDEX(단가설정!$C$11:$C$16,MATCH($E5,단가설정!$A$11:$A$16,0)),"")) | S5: =IF($E5="","",IFERROR(INDEX(단가설정!$D$11:$D$16,MATCH($E5,단가설정!$A$11:$A$16,0)),""))
A6: Y | B6: a) 마스터 템플릿 | C6: 디자인 | D6: 공통 16종 서브페이지 (static 8, gallery 4, board 2, form 2) | E6: UI 디자이너 | F6: 16 | G6: 4800000 | H6: 6400000 | I6: 8800000 | M6: =IF($A6<>"Y",0,IF($J6<>"",$J6,IF($Q6="",$G6,ROUND($G6*(IF($E6="","",IFERROR(INDEX(단가설정!$B$11:$B$16,MATCH($E6,단가설정!$A$11:$A$16,0)),""))/$Q6),0)))) | N6: =IF($A6<>"Y",0,IF($K6<>"",$K6,IF($R6="",$H6,ROUND($H6*(IF($E6="","",IFERROR(INDEX(단가설정!$C$11:$C$16,MATCH($E6,단가설정!$A$11:$A$16,0)),""))/$R6),0)))) | O6: =IF($A6<>"Y",0,IF($L6<>"",$L6,IF($S6="",$I6,ROUND($I6*(IF($E6="","",IFERROR(INDEX(단가설정!$D$11:$D$16,MATCH($E6,단가설정!$A$11:$A$16,0)),""))/$S6),0)))) | Q6: =IF($E6="","",IFERROR(INDEX(단가설정!$B$11:$B$16,MATCH($E6,단가설정!$A$11:$A$16,0)),"")) | R6: =IF($E6="","",IFERROR(INDEX(단가설정!$C$11:$C$16,MATCH($E6,단가설정!$A$11:$A$16,0)),"")) | S6: =IF($E6="","",IFERROR(INDEX(단가설정!$D$11:$D$16,MATCH($E6,단가설정!$A$11:$A$16,0)),""))
A7: Y | B7: a) 마스터 템플릿 | C7: 디자인 | D7: 공통 컴포넌트 5종 (Gallery, Board, Form, Calendar, Static) | E7: UI 디자이너 | F7: 5 | G7: 1500000 | H7: 2000000 | I7: 2750000 | M7: =IF($A7<>"Y",0,IF($J7<>"",$J7,IF($Q7="",$G7,ROUND($G7*(IF($E7="","",IFERROR(INDEX(단가설정!$B$11:$B$16,MATCH($E7,단가설정!$A$11:$A$16,0)),""))/$Q7),0)))) | N7: =IF($A7<>"Y",0,IF($K7<>"",$K7,IF($R7="",$H7,ROUND($H7*(IF($E7="","",IFERROR(INDEX(단가설정!$C$11:$C$16,MATCH($E7,단가설정!$A$11:$A$16,0)),""))/$R7),0)))) | O7: =IF($A7<>"Y",0,IF($L7<>"",$L7,IF($S7="",$I7,ROUND($I7*(IF($E7="","",IFERROR(INDEX(단가설정!$D$11:$D$16,MATCH($E7,단가설정!$A$11:$A$16,0)),""))/$S7),0)))) | Q7: =IF($E7="","",IFERROR(INDEX(단가설정!$B$11:$B$16,MATCH($E7,단가설정!$A$11:$A$16,0)),"")) | R7: =IF($E7="","",IFERROR(INDEX(단가설정!$C$11:$C$16,MATCH($E7,단가설정!$A$11:$A$16,0)),"")) | S7: =IF($E7="","",IFERROR(INDEX(단가설정!$D$11:$D$16,MATCH($E7,단가설정!$A$11:$A$16,0)),""))
A8: Y | B8: a) 마스터 템플릿 | C8: 디자인 | D8: 반응형 Mobile 보완 작업 | E8: UI 디자이너 | F8: 5 | G8: 1500000 | H8: 2000000 | I8: 2750000 | M8: =IF($A8<>"Y",0,IF($J8<>"",$J8,IF($Q8="",$G8,ROUND($G8*(IF($E8="","",IFERROR(INDEX(단가설정!$B$11:$B$16,MATCH($E8,단가설정!$A$11:$A$16,0)),""))/$Q8),0)))) | N8: =IF($A8<>"Y",0,IF($K8<>"",$K8,IF($R8="",$H8,ROUND($H8*(IF($E8="","",IFERROR(INDEX(단가설정!$C$11:$C$16,MATCH($E8,단가설정!$A$11:$A$16,0)),""))/$R8),0)))) | O8: =IF($A8<>"Y",0,IF($L8<>"",$L8,IF($S8="",$I8,ROUND($I8*(IF($E8="","",IFERROR(INDEX(단가설정!$D$11:$D$16,MATCH($E8,단가설정!$A$11:$A$16,0)),""))/$S8),0)))) | Q8: =IF($E8="","",IFERROR(INDEX(단가설정!$B$11:$B$16,MATCH($E8,단가설정!$A$11:$A$16,0)),"")) | R8: =IF($E8="","",IFERROR(INDEX(단가설정!$C$11:$C$16,MATCH($E8,단가설정!$A$11:$A$16,0)),"")) | S8: =IF($E8="","",IFERROR(INDEX(단가설정!$D$11:$D$16,MATCH($E8,단가설정!$A$11:$A$16,0)),""))
A9: Y | B9: a) 마스터 템플릿 | C9: 디자인 | D9: 프로토타이핑/인터랙션 정의 | E9: UX 디자이너 | F9: 3 | G9: 900000 | H9: 1350000 | I9: 1800000 | M9: =IF($A9<>"Y",0,IF($J9<>"",$J9,IF($Q9="",$G9,ROUND($G9*(IF($E9="","",IFERROR(INDEX(단가설정!$B$11:$B$16,MATCH($E9,단가설정!$A$11:$A$16,0)),""))/$Q9),0)))) | N9: =IF($A9<>"Y",0,IF($K9<>"",$K9,IF($R9="",$H9,ROUND($H9*(IF($E9="","",IFERROR(INDEX(단가설정!$C$11:$C$16,MATCH($E9,단가설정!$A$11:$A$16,0)),""))/$R9),0)))) | O9: =IF($A9<>"Y",0,IF($L9<>"",$L9,IF($S9="",$I9,ROUND($I9*(IF($E9="","",IFERROR(INDEX(단가설정!$D$11:$D$16,MATCH($E9,단가설정!$A$11:$A$16,0)),""))/$S9),0)))) | Q9: =IF($E9="","",IFERROR(INDEX(단가설정!$B$11:$B$16,MATCH($E9,단가설정!$A$11:$A$16,0)),"")) | R9: =IF($E9="","",IFERROR(INDEX(단가설정!$C$11:$C$16,MATCH($E9,단가설정!$A$11:$A$16,0)),"")) | S9: =IF($E9="","",IFERROR(INDEX(단가설정!$D$11:$D$16,MATCH($E9,단가설정!$A$11:$A$16,0)),""))
A10: Y | B10: a) 마스터 템플릿 | C10: 프론트엔드 개발 | D10: Next.js + Monorepo 프로젝트 셋업 | E10: 프론트엔드 개발 | F10: 3 | G10: 1200000 | H10: 1500000 | I10: 1950000 | M10: =IF($A10<>"Y",0,IF($J10<>"",$J10,IF($Q10="",$G10,ROUND($G10*(IF($E10="","",IFERROR(INDEX(단가설정!$B$11:$B$16,MATCH($E10,단가설정!$A$11:$A$16,0)),""))/$Q10),0)))) | N10: =IF($A10<>"Y",0,IF($K10<>"",$K10,IF($R10="",$H10,ROUND($H10*(IF($E10="","",IFERROR(INDEX(단가설정!$C$11:$C$16,MATCH($E10,단가설정!$A$11:$A$16,0)),""))/$R10),0)))) | O10: =IF($A10<>"Y",0,IF($L10<>"",$L10,IF($S10="",$I10,ROUND($I10*(IF($E10="","",IFERROR(INDEX(단가설정!$D$11:$D$16,MATCH($E10,단가설정!$A$11:$A$16,0)),""))/$S10),0)))) | Q10: =IF($E10="","",IFERROR(INDEX(단가설정!$B$11:$B$16,MATCH($E10,단가설정!$A$11:$A$16,0)),"")) | R10: =IF($E10="","",IFERROR(INDEX(단가설정!$C$11:$C$16,MATCH($E10,단가설정!$A$11:$A$16,0)),"")) | S10: =IF($E10="","",IFERROR(INDEX(단가설정!$D$11:$D$16,MATCH($E10,단가설정!$A$11:$A$16,0)),""))
A11: Y | B11: a) 마스터 템플릿 | C11: 프론트엔드 개발 | D11: 공통 레이아웃 (Header/GNB/Footer/LNB) | E11: 프론트엔드 개발 | F11: 5 | G11: 2000000 | H11: 2500000 | I11: 3250000 | M11: =IF($A11<>"Y",0,IF($J11<>"",$J11,IF($Q11="",$G11,ROUND($G11*(IF($E11="","",IFERROR(INDEX(단가설정!$B$11:$B$16,MATCH($E11,단가설정!$A$11:$A$16,0)),""))/$Q11),0)))) | N11: =IF($A11<>"Y",0,IF($K11<>"",$K11,IF($R11="",$H11,ROUND($H11*(IF($E11="","",IFERROR(INDEX(단가설정!$C$11:$C$16,MATCH($E11,단가설정!$A$11:$A$16,0)),""))/$R11),0)))) | O11: =IF($A11<>"Y",0,IF($L11<>"",$L11,IF($S11="",$I11,ROUND($I11*(IF($E11="","",IFERROR(INDEX(단가설정!$D$11:$D$16,MATCH($E11,단가설정!$A$11:$A$16,0)),""))/$S11),0)))) | Q11: =IF($E11="","",IFERROR(INDEX(단가설정!$B$11:$B$16,MATCH($E11,단가설정!$A$11:$A$16,0)),"")) | R11: =IF($E11="","",IFERROR(INDEX(단가설정!$C$11:$C$16,MATCH($E11,단가설정!$A$11:$A$16,0)),"")) | S11: =IF($E11="","",IFERROR(INDEX(단가설정!$D$11:$D$16,MATCH($E11,단가설정!$A$11:$A$16,0)),""))
A12: Y | B12: a) 마스터 템플릿 | C12: 프론트엔드 개발 | D12: 공통 16종 페이지 개발 | E12: 프론트엔드 개발 | F12: 16 | G12: 6400000 | H12: 8000000 | I12: 10400000 | M12: =IF($A12<>"Y",0,IF($J12<>"",$J12,IF($Q12="",$G12,ROUND($G12*(IF($E12="","",IFERROR(INDEX(단가설정!$B$11:$B$16,MATCH($E12,단가설정!$A$11:$A$16,0)),""))/$Q12),0)))) | N12: =IF($A12<>"Y",0,IF($K12<>"",$K12,IF($R12="",$H12,ROUND($H12*(IF($E12="","",IFERROR(INDEX(단가설정!$C$11:$C$16,MATCH($E12,단가설정!$A$11:$A$16,0)),""))/$R12),0)))) | O12: =IF($A12<>"Y",0,IF($L12<>"",$L12,IF($S12="",$I12,ROUND($I12*(IF($E12="","",IFERROR(INDEX(단가설정!$D$11:$D$16,MATCH($E12,단가설정!$A$11:$A$16,0)),""))/$S12),0)))) | Q12: =IF($E12="","",IFERROR(INDEX(단가설정!$B$11:$B$16,MATCH($E12,단가설정!$A$11:$A$16,0)),"")) | R12: =IF($E12="","",IFERROR(INDEX(단가설정!$C$11:$C$16,MATCH($E12,단가설정!$A$11:$A$16,0)),"")) | S12: =IF($E12="","",IFERROR(INDEX(단가설정!$D$11:$D$16,MATCH($E12,단가설정!$A$11:$A$16,0)),""))
A13: Y | B13: a) 마스터 템플릿 | C13: 프론트엔드 개발 | D13: 5종 페이지 타입 컴포넌트 라이브러리 | E13: 프론트엔드 개발 | F13: 8 | G13: 3200000 | H13: 4000000 | I13: 5200000 | M13: =IF($A13<>"Y",0,IF($J13<>"",$J13,IF($Q13="",$G13,ROUND($G13*(IF($E13="","",IFERROR(INDEX(단가설정!$B$11:$B$16,MATCH($E13,단가설정!$A$11:$A$16,0)),""))/$Q13),0)))) | N13: =IF($A13<>"Y",0,IF($K13<>"",$K13,IF($R13="",$H13,ROUND($H13*(IF($E13="","",IFERROR(INDEX(단가설정!$C$11:$C$16,MATCH($E13,단가설정!$A$11:$A$16,0)),""))/$R13),0)))) | O13: =IF($A13<>"Y",0,IF($L13<>"",$L13,IF($S13="",$I13,ROUND($I13*(IF($E13="","",IFERROR(INDEX(단가설정!$D$11:$D$16,MATCH($E13,단가설정!$A$11:$A$16,0)),""))/$S13),0)))) | Q13: =IF($E13="","",IFERROR(INDEX(단가설정!$B$11:$B$16,MATCH($E13,단가설정!$A$11:$A$16,0)),"")) | R13: =IF($E13="","",IFERROR(INDEX(단가설정!$C$11:$C$16,MATCH($E13,단가설정!$A$11:$A$16,0)),"")) | S13: =IF($E13="","",IFERROR(INDEX(단가설정!$D$11:$D$16,MATCH($E13,단가설정!$A$11:$A$16,0)),""))
A14: Y | B14: a) 마스터 템플릿 | C14: 프론트엔드 개발 | D14: 하이틴센터 고유 5종 (특강, 다이렉트캐스팅, 섭외뉴스 등) | E14: 프론트엔드 개발 | F14: 5 | G14: 2000000 | H14: 2500000 | I14: 3250000 | M14: =IF($A14<>"Y",0,IF($J14<>"",$J14,IF($Q14="",$G14,ROUND($G14*(IF($E14="","",IFERROR(INDEX(단가설정!$B$11:$B$16,MATCH($E14,단가설정!$A$11:$A$16,0)),""))/$Q14),0)))) | N14: =IF($A14<>"Y",0,IF($K14<>"",$K14,IF($R14="",$H14,ROUND($H14*(IF($E14="","",IFERROR(INDEX(단가설정!$C$11:$C$16,MATCH($E14,단가설정!$A$11:$A$16,0)),""))/$R14),0)))) | O14: =IF($A14<>"Y",0,IF($L14<>"",$L14,IF($S14="",$I14,ROUND($I14*(IF($E14="","",IFERROR(INDEX(단가설정!$D$11:$D$16,MATCH($E14,단가설정!$A$11:$A$16,0)),""))/$S14),0)))) | Q14: =IF($E14="","",IFERROR(INDEX(단가설정!$B$11:$B$16,MATCH($E14,단가설정!$A$11:$A$16,0)),"")) | R14: =IF($E14="","",IFERROR(INDEX(단가설정!$C$11:$C$16,MATCH($E14,단가설정!$A$11:$A$16,0)),"")) | S14: =IF($E14="","",IFERROR(INDEX(단가설정!$D$11:$D$16,MATCH($E14,단가설정!$A$11:$A$16,0)),""))
A15: Y | B15: a) 마스터 템플릿 | C15: 프론트엔드 개발 | D15: 반응형 처리 + 크로스브라우저 | E15: 프론트엔드 개발 | F15: 4 | G15: 1600000 | H15: 2000000 | I15: 2600000 | M15: =IF($A15<>"Y",0,IF($J15<>"",$J15,IF($Q15="",$G15,ROUND($G15*(IF($E15="","",IFERROR(INDEX(단가설정!$B$11:$B$16,MATCH($E15,단가설정!$A$11:$A$16,0)),""))/$Q15),0)))) | N15: =IF($A15<>"Y",0,IF($K15<>"",$K15,IF($R15="",$H15,ROUND($H15*(IF($E15="","",IFERROR(INDEX(단가설정!$C$11:$C$16,MATCH($E15,단가설정!$A$11:$A$16,0)),""))/$R15),0)))) | O15: =IF($A15<>"Y",0,IF($L15<>"",$L15,IF($S15="",$I15,ROUND($I15*(IF($E15="","",IFERROR(INDEX(단가설정!$D$11:$D$16,MATCH($E15,단가설정!$A$11:$A$16,0)),""))/$S15),0)))) | Q15: =IF($E15="","",IFERROR(INDEX(단가설정!$B$11:$B$16,MATCH($E15,단가설정!$A$11:$A$16,0)),"")) | R15: =IF($E15="","",IFERROR(INDEX(단가설정!$C$11:$C$16,MATCH($E15,단가설정!$A$11:$A$16,0)),"")) | S15: =IF($E15="","",IFERROR(INDEX(단가설정!$D$11:$D$16,MATCH($E15,단가설정!$A$11:$A$16,0)),""))
... A19: Y | B19: a-1) 브랜딩 리디자인 | C19: 브랜드 전략 | D19: 브랜드 가이드라인 문서 제작 | E19: UX 디자이너 | F19: 3 | G19: 900000 | H19: 1350000 | I19: 1650000 | M19: =IF($A19<>"Y",0,IF($J19<>"",$J19,IF($Q19="",$G19,ROUND($G19*(IF($E19="","",IFERROR(INDEX(단가설정!$B$11:$B$16,MATCH($E19,단가설정!$A$11:$A$16,0)),""))/$Q19),0)))) | N19: =IF($A19<>"Y",0,IF($K19<>"",$K19,IF($R19="",$H19,ROUND($H19*(IF($E19="","",IFERROR(INDEX(단가설정!$C$11:$C$16,MATCH($E19,단가설정!$A$11:$A$16,0)),""))/$R19),0)))) | O19: =IF($A19<>"Y",0,IF($L19<>"",$L19,IF($S19="",$I19,ROUND($I19*(IF($E19="","",IFERROR(INDEX(단가설정!$D$11:$D$16,MATCH($E19,단가설정!$A$11:$A$16,0)),""))/$S19),0)))) | Q19: =IF($E19="","",IFERROR(INDEX(단가설정!$B$11:$B$16,MATCH($E19,단가설정!$A$11:$A$16,0)),"")) | R19: =IF($E19="","",IFERROR(INDEX(단가설정!$C$11:$C$16,MATCH($E19,단가설정!$A$11:$A$16,0)),"")) | S19: =IF($E19="","",IFERROR(INDEX(단가설정!$D$11:$D$16,MATCH($E19,단가설정!$A$11:$A$16,0)),""))
A20: Y | B20: b) 브랜드 커스터마이징 | C20: 아트센터 | D20: 브랜드 디자인 적용 (색상/이미지/로고 교체) | E20: UI 디자이너 | G20: 600000 | H20: 800000 | I20: 1100000 | M20: =IF($A20<>"Y",0,IF($J20<>"",$J20,IF($Q20="",$G20,ROUND($G20*(IF($E20="","",IFERROR(INDEX(단가설정!$B$11:$B$16,MATCH($E20,단가설정!$A$11:$A$16,0)),""))/$Q20),0)))) | N20: =IF($A20<>"Y",0,IF($K20<>"",$K20,IF($R20="",$H20,ROUND($H20*(IF($E20="","",IFERROR(INDEX(단가설정!$C$11:$C$16,MATCH($E20,단가설정!$A$11:$A$16,0)),""))/$R20),0)))) | O20: =IF($A20<>"Y",0,IF($L20<>"",$L20,IF($S20="",$I20,ROUND($I20*(IF($E20="","",IFERROR(INDEX(단가설정!$D$11:$D$16,MATCH($E20,단가설정!$A$11:$A$16,0)),""))/$S20),0)))) | Q20: =IF($E20="","",IFERROR(INDEX(단가설정!$B$11:$B$16,MATCH($E20,단가설정!$A$11:$A$16,0)),"")) | R20: =IF($E20="","",IFERROR(INDEX(단가설정!$C$11:$C$16,MATCH($E20,단가설정!$A$11:$A$16,0)),"")) | S20: =IF($E20="","",IFERROR(INDEX(단가설정!$D$11:$D$16,MATCH($E20,단가설정!$A$11:$A$16,0)),""))
A21: Y | B21: b) 브랜드 커스터마이징 | C21: 아트센터 | D21: 고유 5종 디자인 (센터소개, 매니저소개, 출신아티스트, 촬영후기, 오디션폼) | E21: UI 디자이너 | G21: 1500000 | H21: 2000000 | I21: 2750000 | M21: =IF($A21<>"Y",0,IF($J21<>"",$J21,IF($Q21="",$G21,ROUND($G21*(IF($E21="","",IFERROR(INDEX(단가설정!$B$11:$B$16,MATCH($E21,단가설정!$A$11:$A$16,0)),""))/$Q21),0)))) | N21: =IF($A21<>"Y",0,IF($K21<>"",$K21,IF($R21="",$H21,ROUND($H21*(IF($E21="","",IFERROR(INDEX(단가설정!$C$11:$C$16,MATCH($E21,단가설정!$A$11:$A$16,0)),""))/$R21),0)))) | O21: =IF($A21<>"Y",0,IF($L21<>"",$L21,IF($S21="",$I21,ROUND($I21*(IF($E21="","",IFERROR(INDEX(단가설정!$D$11:$D$16,MATCH($E21,단가설정!$A$11:$A$16,0)),""))/$S21),0)))) | Q21: =IF($E21="","",IFERROR(INDEX(단가설정!$B$11:$B$16,MATCH($E21,단가설정!$A$11:$A$16,0)),"")) | R21: =IF($E21="","",IFERROR(INDEX(단가설정!$C$11:$C$16,MATCH($E21,단가설정!$A$11:$A$16,0)),"")) | S21: =IF($E21="","",IFERROR(INDEX(단가설정!$D$11:$D$16,MATCH($E21,단가설정!$A$11:$A$16,0)),""))
A22: Y | B22: b) 브랜드 커스터마이징 | C22: 아트센터 | D22: 고유 5종 개발 | E22: 프론트엔드 개발 | G22: 2000000 | H22: 2500000 | I22: 3250000 | M22: =IF($A22<>"Y",0,IF($J22<>"",$J22,IF($Q22="",$G22,ROUND($G22*(IF($E22="","",IFERROR(INDEX(단가설정!$B$11:$B$16,MATCH($E22,단가설정!$A$11:$A$16,0)),""))/$Q22),0)))) | N22: =IF($A22<>"Y",0,IF($K22<>"",$K22,IF($R22="",$H22,ROUND($H22*(IF($E22="","",IFERROR(INDEX(단가설정!$C$11:$C$16,MATCH($E22,단가설정!$A$11:$A$16,0)),""))/$R22),0)))) | O22: =IF($A22<>"Y",0,IF($L22<>"",$L22,IF($S22="",$I22,ROUND($I22*(IF($E22="","",IFERROR(INDEX(단가설정!$D$11:$D$16,MATCH($E22,단가설정!$A$11:$A$16,0)),""))/$S22),0)))) | Q22: =IF($E22="","",IFERROR(INDEX(단가설정!$B$11:$B$16,MATCH($E22,단가설정!$A$11:$A$16,0)),"")) | R22: =IF($E22="","",IFERROR(INDEX(단가설정!$C$11:$C$16,MATCH($E22,단가설정!$A$11:$A$16,0)),"")) | S22: =IF($E22="","",IFERROR(INDEX(단가설정!$D$11:$D$16,MATCH($E22,단가설정!$A$11:$A$16,0)),""))
A23: Y | B23: b) 브랜드 커스터마이징 | C23: 입시센터 | D23: 브랜드 디자인 적용 | E23: UI 디자이너 | G23: 600000 | H23: 800000 | I23: 1100000 | M23: =IF($A23<>"Y",0,IF($J23<>"",$J23,IF($Q23="",$G23,ROUND($G23*(IF($E23="","",IFERROR(INDEX(단가설정!$B$11:$B$16,MATCH($E23,단가설정!$A$11:$A$16,0)),""))/$Q23),0)))) | N23: =IF($A23<>"Y",0,IF($K23<>"",$K23,IF($R23="",$H23,ROUND($H23*(IF($E23="","",IFERROR(INDEX(단가설정!$C$11:$C$16,MATCH($E23,단가설정!$A$11:$A$16,0)),""))/$R23),0)))) | O23: =IF($A23<>"Y",0,IF($L23<>"",$L23,IF($S23="",$I23,ROUND($I23*(IF($E23="","",IFERROR(INDEX(단가설정!$D$11:$D$16,MATCH($E23,단가설정!$A$11:$A$16,0)),""))/$S23),0)))) | Q23: =IF($E23="","",IFERROR(INDEX(단가설정!$B$11:$B$16,MATCH($E23,단가설정!$A$11:$A$16,0)),"")) | R23: =IF($E23="","",IFERROR(INDEX(단가설정!$C$11:$C$16,MATCH($E23,단가설정!$A$11:$A$16,0)),"")) | S23: =IF($E23="","",IFERROR(INDEX(단가설정!$D$11:$D$16,MATCH($E23,단가설정!$A$11:$A$16,0)),""))
A24: Y | B24: b) 브랜드 커스터마이징 | C24: 입시센터 | D24: 고유 13종 디자인 (커리큘럼 5, 합격현황 2, 후기/영상, 장학, 연혁 등) | E24: UI 디자이너 | G24: 3900000 | H24: 5200000 | I24: 7150000 | M24: =IF($A24<>"Y",0,IF($J24<>"",$J24,IF($Q24="",$G24,ROUND($G24*(IF($E24="","",IFERROR(INDEX(단가설정!$B$11:$B$16,MATCH($E24,단가설정!$A$11:$A$16,0)),""))/$Q24),0)))) | N24: =IF($A24<>"Y",0,IF($K24<>"",$K24,IF($R24="",$H24,ROUND($H24*(IF($E24="","",IFERROR(INDEX(단가설정!$C$11:$C$16,MATCH($E24,단가설정!$A$11:$A$16,0)),""))/$R24),0)))) | O24: =IF($A24<>"Y",0,IF($L24<>"",$L24,IF($S24="",$I24,ROUND($I24*(IF($E24="","",IFERROR(INDEX(단가설정!$D$11:$D$16,MATCH($E24,단가설정!$A$11:$A$16,0)),""))/$S24),0)))) | Q24: =IF($E24="","",IFERROR(INDEX(단가설정!$B$11:$B$16,MATCH($E24,단가설정!$A$11:$A$16,0)),"")) | R24: =IF($E24="","",IFERROR(INDEX(단가설정!$C$11:$C$16,MATCH($E24,단가설정!$A$11:$A$16,0)),"")) | S24: =IF($E24="","",IFERROR(INDEX(단가설정!$D$11:$D$16,MATCH($E24,단가설정!$A$11:$A$16,0)),""))
A25: Y | B25: b) 브랜드 커스터마이징 | C25: 입시센터 | D25: 고유 13종 개발 | E25: 프론트엔드 개발 | G25: 5200000 | H25: 6500000 | I25: 8450000 | M25: =IF($A25<>"Y",0,IF($J25<>"",$J25,IF($Q25="",$G25,ROUND($G25*(IF($E25="","",IFERROR(INDEX(단가설정!$B$11:$B$16,MATCH($E25,단가설정!$A$11:$A$16,0)),""))/$Q25),0)))) | N25: =IF($A25<>"Y",0,IF($K25<>"",$K25,IF($R25="",$H25,ROUND($H25*(IF($E25="","",IFERROR(INDEX(단가설정!$C$11:$C$16,MATCH($E25,단가설정!$A$11:$A$16,0)),""))/$R25),0)))) | O25: =IF($A25<>"Y",0,IF($L25<>"",$L25,IF($S25="",$I25,ROUND($I25*(IF($E25="","",IFERROR(INDEX(단가설정!$D$11:$D$16,MATCH($E25,단가설정!$A$11:$A$16,0)),""))/$S25),0)))) | Q25: =IF($E25="","",IFERROR(INDEX(단가설정!$B$11:$B$16,MATCH($E25,단가설정!$A$11:$A$16,0)),"")) | R25: =IF($E25="","",IFERROR(INDEX(단가설정!$C$11:$C$16,MATCH($E25,단가설정!$A$11:$A$16,0)),"")) | S25: =IF($E25="","",IFERROR(INDEX(단가설정!$D$11:$D$16,MATCH($E25,단가설정!$A$11:$A$16,0)),""))
A26: Y | B26: b) 브랜드 커스터마이징 | C26: 키즈센터 | D26: 브랜드 디자인 적용 | E26: UI 디자이너 | G26: 600000 | H26: 800000 | I26: 1100000 | M26: =IF($A26<>"Y",0,IF($J26<>"",$J26,IF($Q26="",$G26,ROUND($G26*(IF($E26="","",IFERROR(INDEX(단가설정!$B$11:$B$16,MATCH($E26,단가설정!$A$11:$A$16,0)),""))/$Q26),0)))) | N26: =IF($A26<>"Y",0,IF($K26<>"",$K26,IF($R26="",$H26,ROUND($H26*(IF($E26="","",IFERROR(INDEX(단가설정!$C$11:$C$16,MATCH($E26,단가설정!$A$11:$A$16,0)),""))/$R26),0)))) | O26: =IF($A26<>"Y",0,IF($L26<>"",$L26,IF($S26="",$I26,ROUND($I26*(IF($E26="","",IFERROR(INDEX(단가설정!$D$11:$D$16,MATCH($E26,단가설정!$A$11:$A$16,0)),""))/$S26),0)))) | Q26: =IF($E26="","",IFERROR(INDEX(단가설정!$B$11:$B$16,MATCH($E26,단가설정!$A$11:$A$16,0)),"")) | R26: =IF($E26="","",IFERROR(INDEX(단가설정!$C$11:$C$16,MATCH($E26,단가설정!$A$11:$A$16,0)),"")) | S26: =IF($E26="","",IFERROR(INDEX(단가설정!$D$11:$D$16,MATCH($E26,단가설정!$A$11:$A$16,0)),""))
A27: Y | B27: b) 브랜드 커스터마이징 | C27: 키즈센터 | D27: 고유 5종 디자인 (교육과정 3, 추가 캐스팅보드 2) | E27: UI 디자이너 | G27: 1500000 | H27: 2000000 | I27: 2750000 | M27: =IF($A27<>"Y",0,IF($J27<>"",$J27,IF($Q27="",$G27,ROUND($G27*(IF($E27="","",IFERROR(INDEX(단가설정!$B$11:$B$16,MATCH($E27,단가설정!$A$11:$A$16,0)),""))/$Q27),0)))) | N27: =IF($A27<>"Y",0,IF($K27<>"",$K27,IF($R27="",$H27,ROUND($H27*(IF($E27="","",IFERROR(INDEX(단가설정!$C$11:$C$16,MATCH($E27,단가설정!$A$11:$A$16,0)),""))/$R27),0)))) | O27: =IF($A27<>"Y",0,IF($L27<>"",$L27,IF($S27="",$I27,ROUND($I27*(IF($E27="","",IFERROR(INDEX(단가설정!$D$11:$D$16,MATCH($E27,단가설정!$A$11:$A$16,0)),""))/$S27),0)))) | Q27: =IF($E27="","",IFERROR(INDEX(단가설정!$B$11:$B$16,MATCH($E27,단가설정!$A$11:$A$16,0)),"")) | R27: =IF($E27="","",IFERROR(INDEX(단가설정!$C$11:$C$16,MATCH($E27,단가설정!$A$11:$A$16,0)),"")) | S27: =IF($E27="","",IFERROR(INDEX(단가설정!$D$11:$D$16,MATCH($E27,단가설정!$A$11:$A$16,0)),""))
A28: Y | B28: b) 브랜드 커스터마이징 | C28: 키즈센터 | D28: 고유 5종 개발 | E28: 프론트엔드 개발 | G28: 2000000 | H28: 2500000 | I28: 3250000 | M28: =IF($A28<>"Y",0,IF($J28<>"",$J28,IF($Q28="",$G28,ROUND($G28*(IF($E28="","",IFERROR(INDEX(단가설정!$B$11:$B$16,MATCH($E28,단가설정!$A$11:$A$16,0)),""))/$Q28),0)))) | N28: =IF($A28<>"Y",0,IF($K28<>"",$K28,IF($R28="",$H28,ROUND($H28*(IF($E28="","",IFERROR(INDEX(단가설정!$C$11:$C$16,MATCH($E28,단가설정!$A$11:$A$16,0)),""))/$R28),0)))) | O28: =IF($A28<>"Y",0,IF($L28<>"",$L28,IF($S28="",$I28,ROUND($I28*(IF($E28="","",IFERROR(INDEX(단가설정!$D$11:$D$16,MATCH($E28,단가설정!$A$11:$A$16,0)),""))/$S28),0)))) | Q28: =IF($E28="","",IFERROR(INDEX(단가설정!$B$11:$B$16,MATCH($E28,단가설정!$A$11:$A$16,0)),"")) | R28: =IF($E28="","",IFERROR(INDEX(단가설정!$C$11:$C$16,MATCH($E28,단가설정!$A$11:$A$16,0)),"")) | S28: =IF($E28="","",IFERROR(INDEX(단가설정!$D$11:$D$16,MATCH($E28,단가설정!$A$11:$A$16,0)),""))
A29: Y | B29: c) 공통 기능 | C29: CMS/플랫폼 | D29: Payload CMS 셋업 + 콘텐츠 모델링 (5개 브랜드) | E29: 백엔드/CMS 개발 | F29: 10 | G29: 4000000 | H29: 5000000 | I29: 6500000 | M29: =IF($A29<>"Y",0,IF($J29<>"",$J29,IF($Q29="",$G29,ROUND($G29*(IF($E29="","",IFERROR(INDEX(단가설정!$B$11:$B$16,MATCH($E29,단가설정!$A$11:$A$16,0)),""))/$Q29),0)))) | N29: =IF($A29<>"Y",0,IF($K29<>"",$K29,IF($R29="",$H29,ROUND($H29*(IF($E29="","",IFERROR(INDEX(단가설정!$C$11:$C$16,MATCH($E29,단가설정!$A$11:$A$16,0)),""))/$R29),0)))) | O29: =IF($A29<>"Y",0,IF($L29<>"",$L29,IF($S29="",$I29,ROUND($I29*(IF($E29="","",IFERROR(INDEX(단가설정!$D$11:$D$16,MATCH($E29,단가설정!$A$11:$A$16,0)),""))/$S29),0)))) | Q29: =IF($E29="","",IFERROR(INDEX(단가설정!$B$11:$B$16,MATCH($E29,단가설정!$A$11:$A$16,0)),"")) | R29: =IF($E29="","",IFERROR(INDEX(단가설정!$C$11:$C$16,MATCH($E29,단가설정!$A$11:$A$16,0)),"")) | S29: =IF($E29="","",IFERROR(INDEX(단가설정!$D$11:$D$16,MATCH($E29,단가설정!$A$11:$A$16,0)),""))
A30: Y | B30: c) 공통 기능 | C30: CMS/플랫폼 | D30: CMS 어드민 UI 커스터마이징 + 권한 관리 | E30: 백엔드/CMS 개발 | F30: 5 | G30: 2000000 | H30: 2500000 | I30: 3250000 | M30: =IF($A30<>"Y",0,IF($J30<>"",$J30,IF($Q30="",$G30,ROUND($G30*(IF($E30="","",IFERROR(INDEX(단가설정!$B$11:$B$16,MATCH($E30,단가설정!$A$11:$A$16,0)),""))/$Q30),0)))) | N30: =IF($A30<>"Y",0,IF($K30<>"",$K30,IF($R30="",$H30,ROUND($H30*(IF($E30="","",IFERROR(INDEX(단가설정!$C$11:$C$16,MATCH($E30,단가설정!$A$11:$A$16,0)),""))/$R30),0)))) | O30: =IF($A30<>"Y",0,IF($L30<>"",$L30,IF($S30="",$I30,ROUND($I30*(IF($E30="","",IFERROR(INDEX(단가설정!$D$11:$D$16,MATCH($E30,단가설정!$A$11:$A$16,0)),""))/$S30),0)))) | Q30: =IF($E30="","",IFERROR(INDEX(단가설정!$B$11:$B$16,MATCH($E30,단가설정!$A$11:$A$16,0)),"")) | R30: =IF($E30="","",IFERROR(INDEX(단가설정!$C$11:$C$16,MATCH($E30,단가설정!$A$11:$A$16,0)),"")) | S30: =IF($E30="","",IFERROR(INDEX(단가설정!$D$11:$D$16,MATCH($E30,단가설정!$A$11:$A$16,0)),""))
A31: Y | B31: c) 공통 기능 | C31: CMS/플랫폼 | D31: 통합 상담 폼 (5개 센터 선택 + API + 알림) | E31: 백엔드/CMS 개발 | F31: 5 | G31: 2000000 | H31: 2500000 | I31: 3250000 | M31: =IF($A31<>"Y",0,IF($J31<>"",$J31,IF($Q31="",$G31,ROUND($G31*(IF($E31="","",IFERROR(INDEX(단가설정!$B$11:$B$16,MATCH($E31,단가설정!$A$11:$A$16,0)),""))/$Q31),0)))) | N31: =IF($A31<>"Y",0,IF($K31<>"",$K31,IF($R31="",$H31,ROUND($H31*(IF($E31="","",IFERROR(INDEX(단가설정!$C$11:$C$16,MATCH($E31,단가설정!$A$11:$A$16,0)),""))/$R31),0)))) | O31: =IF($A31<>"Y",0,IF($L31<>"",$L31,IF($S31="",$I31,ROUND($I31*(IF($E31="","",IFERROR(INDEX(단가설정!$D$11:$D$16,MATCH($E31,단가설정!$A$11:$A$16,0)),""))/$S31),0)))) | Q31: =IF($E31="","",IFERROR(INDEX(단가설정!$B$11:$B$16,MATCH($E31,단가설정!$A$11:$A$16,0)),"")) | R31: =IF($E31="","",IFERROR(INDEX(단가설정!$C$11:$C$16,MATCH($E31,단가설정!$A$11:$A$16,0)),"")) | S31: =IF($E31="","",IFERROR(INDEX(단가설정!$D$11:$D$16,MATCH($E31,단가설정!$A$11:$A$16,0)),""))
A32: Y | B32: c) 공통 기능 | C32: CMS/플랫폼 | D32: 통합 관리자 대시보드 (센터별 상담 조회/관리) | E32: 백엔드/CMS 개발 | F32: 6 | G32: 2400000 | H32: 3000000 | I32: 3900000 | M32: =IF($A32<>"Y",0,IF($J32<>"",$J32,IF($Q32="",$G32,ROUND($G32*(IF($E32="","",IFERROR(INDEX(단가설정!$B$11:$B$16,MATCH($E32,단가설정!$A$11:$A$16,0)),""))/$Q32),0)))) | N32: =IF($A32<>"Y",0,IF($K32<>"",$K32,IF($R32="",$H32,ROUND($H32*(IF($E32="","",IFERROR(INDEX(단가설정!$C$11:$C$16,MATCH($E32,단가설정!$A$11:$A$16,0)),""))/$R32),0)))) | O32: =IF($A32<>"Y",0,IF($L32<>"",$L32,IF($S32="",$I32,ROUND($I32*(IF($E32="","",IFERROR(INDEX(단가설정!$D$11:$D$16,MATCH($E32,단가설정!$A$11:$A$16,0)),""))/$S32),0)))) | Q32: =IF($E32="","",IFERROR(INDEX(단가설정!$B$11:$B$16,MATCH($E32,단가설정!$A$11:$A$16,0)),"")) | R32: =IF($E32="","",IFERROR(INDEX(단가설정!$C$11:$C$16,MATCH($E32,단가설정!$A$11:$A$16,0)),"")) | S32: =IF($E32="","",IFERROR(INDEX(단가설정!$D$11:$D$16,MATCH($E32,단가설정!$A$11:$A$16,0)),""))
A33: Y | B33: c) 공통 기능 | C33: CMS/플랫폼 | D33: 그누보드 데이터 마이그레이션 스크립트 | E33: 백엔드/CMS 개발 | F33: 5 | G33: 2000000 | H33: 2500000 | I33: 3250000 | M33: =IF($A33<>"Y",0,IF($J33<>"",$J33,IF($Q33="",$G33,ROUND($G33*(IF($E33="","",IFERROR(INDEX(단가설정!$B$11:$B$16,MATCH($E33,단가설정!$A$11:$A$16,0)),""))/$Q33),0)))) | N33: =IF($A33<>"Y",0,IF($K33<>"",$K33,IF($R33="",$H33,ROUND($H33*(IF($E33="","",IFERROR(INDEX(단가설정!$C$11:$C$16,MATCH($E33,단가설정!$A$11:$A$16,0)),""))/$R33),0)))) | O33: =IF($A33<>"Y",0,IF($L33<>"",$L33,IF($S33="",$I33,ROUND($I33*(IF($E33="","",IFERROR(INDEX(단가설정!$D$11:$D$16,MATCH($E33,단가설정!$A$11:$A$16,0)),""))/$S33),0)))) | Q33: =IF($E33="","",IFERROR(INDEX(단가설정!$B$11:$B$16,MATCH($E33,단가설정!$A$11:$A$16,0)),"")) | R33: =IF($E33="","",IFERROR(INDEX(단가설정!$C$11:$C$16,MATCH($E33,단가설정!$A$11:$A$16,0)),"")) | S33: =IF($E33="","",IFERROR(INDEX(단가설정!$D$11:$D$16,MATCH($E33,단가설정!$A$11:$A$16,0)),""))
A34: Y | B34: c) 공통 기능 | C34: CMS/플랫폼 | D34: 공통 API 레이어 + 타입 공유 (Monorepo) | E34: 백엔드/CMS 개발 | F34: 4 | G34: 1600000 | H34: 2000000 | I34: 2600000 | M34: =IF($A34<>"Y",0,IF($J34<>"",$J34,IF($Q34="",$G34,ROUND($G34*(IF($E34="","",IFERROR(INDEX(단가설정!$B$11:$B$16,MATCH($E34,단가설정!$A$11:$A$16,0)),""))/$Q34),0)))) | N34: =IF($A34<>"Y",0,IF($K34<>"",$K34,IF($R34="",$H34,ROUND($H34*(IF($E34="","",IFERROR(INDEX(단가설정!$C$11:$C$16,MATCH($E34,단가설정!$A$11:$A$16,0)),""))/$R34),0)))) | O34: =IF($A34<>"Y",0,IF($L34<>"",$L34,IF($S34="",$I34,ROUND($I34*(IF($E34="","",IFERROR(INDEX(단가설정!$D$11:$D$16,MATCH($E34,단가설정!$A$11:$A$16,0)),""))/$S34),0)))) | Q34: =IF($E34="","",IFERROR(INDEX(단가설정!$B$11:$B$16,MATCH($E34,단가설정!$A$11:$A$16,0)),"")) | R34: =IF($E34="","",IFERROR(INDEX(단가설정!$C$11:$C$16,MATCH($E34,단가설정!$A$11:$A$16,0)),"")) | S34: =IF($E34="","",IFERROR(INDEX(단가설정!$D$11:$D$16,MATCH($E34,단가설정!$A$11:$A$16,0)),""))
A35: Y | B35: d) SEO/GEO 인프라 | C35: SEO/GEO | D35: 클린 URL 설계 + 301 리다이렉트 맵 (126페이지 전체) | E35: 프론트엔드 개발 | G35: 1000000 | H35: 1500000 | I35: 2000000 | M35: =IF($A35<>"Y",0,IF($J35<>"",$J35,IF($Q35="",$G35,ROUND($G35*(IF($E35="","",IFERROR(INDEX(단가설정!$B$11:$B$16,MATCH($E35,단가설정!$A$11:$A$16,0)),""))/$Q35),0)))) | N35: =IF($A35<>"Y",0,IF($K35<>"",$K35,IF($R35="",$H35,ROUND($H35*(IF($E35="","",IFERROR(INDEX(단가설정!$C$11:$C$16,MATCH($E35,단가설정!$A$11:$A$16,0)),""))/$R35),0)))) | O35: =IF($A35<>"Y",0,IF($L35<>"",$L35,IF($S35="",$I35,ROUND($I35*(IF($E35="","",IFERROR(INDEX(단가설정!$D$11:$D$16,MATCH($E35,단가설정!$A$11:$A$16,0)),""))/$S35),0)))) | Q35: =IF($E35="","",IFERROR(INDEX(단가설정!$B$11:$B$16,MATCH($E35,단가설정!$A$11:$A$16,0)),"")) | R35: =IF($E35="","",IFERROR(INDEX(단가설정!$C$11:$C$16,MATCH($E35,단가설정!$A$11:$A$16,0)),"")) | S35: =IF($E35="","",IFERROR(INDEX(단가설정!$D$11:$D$16,MATCH($E35,단가설정!$A$11:$A$16,0)),""))
A36: Y | B36: d) SEO/GEO 인프라 | C36: SEO/GEO | D36: Schema.org 구조화 데이터 (5개 사이트 × 5종 스키마) | E36: 프론트엔드 개발 | G36: 2000000 | H36: 3000000 | I36: 4000000 | M36: =IF($A36<>"Y",0,IF($J36<>"",$J36,IF($Q36="",$G36,ROUND($G36*(IF($E36="","",IFERROR(INDEX(단가설정!$B$11:$B$16,MATCH($E36,단가설정!$A$11:$A$16,0)),""))/$Q36),0)))) | N36: =IF($A36<>"Y",0,IF($K36<>"",$K36,IF($R36="",$H36,ROUND($H36*(IF($E36="","",IFERROR(INDEX(단가설정!$C$11:$C$16,MATCH($E36,단가설정!$A$11:$A$16,0)),""))/$R36),0)))) | O36: =IF($A36<>"Y",0,IF($L36<>"",$L36,IF($S36="",$I36,ROUND($I36*(IF($E36="","",IFERROR(INDEX(단가설정!$D$11:$D$16,MATCH($E36,단가설정!$A$11:$A$16,0)),""))/$S36),0)))) | Q36: =IF($E36="","",IFERROR(INDEX(단가설정!$B$11:$B$16,MATCH($E36,단가설정!$A$11:$A$16,0)),"")) | R36: =IF($E36="","",IFERROR(INDEX(단가설정!$C$11:$C$16,MATCH($E36,단가설정!$A$11:$A$16,0)),"")) | S36: =IF($E36="","",IFERROR(INDEX(단가설정!$D$11:$D$16,MATCH($E36,단가설정!$A$11:$A$16,0)),""))
A37: Y | B37: d) SEO/GEO 인프라 | C37: SEO/GEO | D37: 페이지별 동적 메타 (title/description/OG/canonical) | E37: 프론트엔드 개발 | G37: 1000000 | H37: 1500000 | I37: 2000000 | M37: =IF($A37<>"Y",0,IF($J37<>"",$J37,IF($Q37="",$G37,ROUND($G37*(IF($E37="","",IFERROR(INDEX(단가설정!$B$11:$B$16,MATCH($E37,단가설정!$A$11:$A$16,0)),""))/$Q37),0)))) | N37: =IF($A37<>"Y",0,IF($K37<>"",$K37,IF($R37="",$H37,ROUND($H37*(IF($E37="","",IFERROR(INDEX(단가설정!$C$11:$C$16,MATCH($E37,단가설정!$A$11:$A$16,0)),""))/$R37),0)))) | O37: =IF($A37<>"Y",0,IF($L37<>"",$L37,IF($S37="",$I37,ROUND($I37*(IF($E37="","",IFERROR(INDEX(단가설정!$D$11:$D$16,MATCH($E37,단가설정!$A$11:$A$16,0)),""))/$S37),0)))) | Q37: =IF($E37="","",IFERROR(INDEX(단가설정!$B$11:$B$16,MATCH($E37,단가설정!$A$11:$A$16,0)),"")) | R37: =IF($E37="","",IFERROR(INDEX(단가설정!$C$11:$C$16,MATCH($E37,단가설정!$A$11:$A$16,0)),"")) | S37: =IF($E37="","",IFERROR(INDEX(단가설정!$D$11:$D$16,MATCH($E37,단가설정!$A$11:$A$16,0)),""))
A38: Y | B38: d) SEO/GEO 인프라 | C38: SEO/GEO | D38: sitemap.xml 자동 생성 + robots.txt (5개 사이트) | E38: 프론트엔드 개발 | G38: 500000 | H38: 800000 | I38: 1000000 | M38: =IF($A38<>"Y",0,IF($J38<>"",$J38,IF($Q38="",$G38,ROUND($G38*(IF($E38="","",IFERROR(INDEX(단가설정!$B$11:$B$16,MATCH($E38,단가설정!$A$11:$A$16,0)),""))/$Q38),0)))) | N38: =IF($A38<>"Y",0,IF($K38<>"",$K38,IF($R38="",$H38,ROUND($H38*(IF($E38="","",IFERROR(INDEX(단가설정!$C$11:$C$16,MATCH($E38,단가설정!$A$11:$A$16,0)),""))/$R38),0)))) | O38: =IF($A38<>"Y",0,IF($L38<>"",$L38,IF($S38="",$I38,ROUND($I38*(IF($E38="","",IFERROR(INDEX(단가설정!$D$11:$D$16,MATCH($E38,단가설정!$A$11:$A$16,0)),""))/$S38),0)))) | Q38: =IF($E38="","",IFERROR(INDEX(단가설정!$B$11:$B$16,MATCH($E38,단가설정!$A$11:$A$16,0)),"")) | R38: =IF($E38="","",IFERROR(INDEX(단가설정!$C$11:$C$16,MATCH($E38,단가설정!$A$11:$A$16,0)),"")) | S38: =IF($E38="","",IFERROR(INDEX(단가설정!$D$11:$D$16,MATCH($E38,단가설정!$A$11:$A$16,0)),""))
A39: Y | B39: d) SEO/GEO 인프라 | C39: SEO/GEO | D39: llms.txt 작성 (5개 사이트) | E39: 프론트엔드 개발 | G39: 500000 | H39: 800000 | I39: 1000000 | M39: =IF($A39<>"Y",0,IF($J39<>"",$J39,IF($Q39="",$G39,ROUND($G39*(IF($E39="","",IFERROR(INDEX(단가설정!$B$11:$B$16,MATCH($E39,단가설정!$A$11:$A$16,0)),""))/$Q39),0)))) | N39: =IF($A39<>"Y",0,IF($K39<>"",$K39,IF($R39="",$H39,ROUND($H39*(IF($E39="","",IFERROR(INDEX(단가설정!$C$11:$C$16,MATCH($E39,단가설정!$A$11:$A$16,0)),""))/$R39),0)))) | O39: =IF($A39<>"Y",0,IF($L39<>"",$L39,IF($S39="",$I39,ROUND($I39*(IF($E39="","",IFERROR(INDEX(단가설정!$D$11:$D$16,MATCH($E39,단가설정!$A$11:$A$16,0)),""))/$S39),0)))) | Q39: =IF($E39="","",IFERROR(INDEX(단가설정!$B$11:$B$16,MATCH($E39,단가설정!$A$11:$A$16,0)),"")) | R39: =IF($E39="","",IFERROR(INDEX(단가설정!$C$11:$C$16,MATCH($E39,단가설정!$A$11:$A$16,0)),"")) | S39: =IF($E39="","",IFERROR(INDEX(단가설정!$D$11:$D$16,MATCH($E39,단가설정!$A$11:$A$16,0)),""))
A40: Y | B40: d) SEO/GEO 인프라 | C40: SEO/GEO | D40: Core Web Vitals 최적화 (LCP/CLS/INP) | E40: 프론트엔드 개발 | G40: 1000000 | H40: 1500000 | I40: 2000000 | M40: =IF($A40<>"Y",0,IF($J40<>"",$J40,IF($Q40="",$G40,ROUND($G40*(IF($E40="","",IFERROR(INDEX(단가설정!$B$11:$B$16,MATCH($E40,단가설정!$A$11:$A$16,0)),""))/$Q40),0)))) | N40: =IF($A40<>"Y",0,IF($K40<>"",$K40,IF($R40="",$H40,ROUND($H40*(IF($E40="","",IFERROR(INDEX(단가설정!$C$11:$C$16,MATCH($E40,단가설정!$A$11:$A$16,0)),""))/$R40),0)))) | O40: =IF($A40<>"Y",0,IF($L40<>"",$L40,IF($S40="",$I40,ROUND($I40*(IF($E40="","",IFERROR(INDEX(단가설정!$D$11:$D$16,MATCH($E40,단가설정!$A$11:$A$16,0)),""))/$S40),0)))) | Q40: =IF($E40="","",IFERROR(INDEX(단가설정!$B$11:$B$16,MATCH($E40,단가설정!$A$11:$A$16,0)),"")) | R40: =IF($E40="","",IFERROR(INDEX(단가설정!$C$11:$C$16,MATCH($E40,단가설정!$A$11:$A$16,0)),"")) | S40: =IF($E40="","",IFERROR(INDEX(단가설정!$D$11:$D$16,MATCH($E40,단가설정!$A$11:$A$16,0)),""))
A41: Y | B41: d) SEO/GEO 인프라 | C41: SEO/GEO | D41: Google Search Console + 사이트맵 제출 (5개) | E41: PM | G41: 500000 | H41: 800000 | I41: 1000000 | M41: =IF($A41<>"Y",0,IF($J41<>"",$J41,IF($Q41="",$G41,ROUND($G41*(IF($E41="","",IFERROR(INDEX(단가설정!$B$11:$B$16,MATCH($E41,단가설정!$A$11:$A$16,0)),""))/$Q41),0)))) | N41: =IF($A41<>"Y",0,IF($K41<>"",$K41,IF($R41="",$H41,ROUND($H41*(IF($E41="","",IFERROR(INDEX(단가설정!$C$11:$C$16,MATCH($E41,단가설정!$A$11:$A$16,0)),""))/$R41),0)))) | O41: =IF($A41<>"Y",0,IF($L41<>"",$L41,IF($S41="",$I41,ROUND($I41*(IF($E41="","",IFERROR(INDEX(단가설정!$D$11:$D$16,MATCH($E41,단가설정!$A$11:$A$16,0)),""))/$S41),0)))) | Q41: =IF($E41="","",IFERROR(INDEX(단가설정!$B$11:$B$16,MATCH($E41,단가설정!$A$11:$A$16,0)),"")) | R41: =IF($E41="","",IFERROR(INDEX(단가설정!$C$11:$C$16,MATCH($E41,단가설정!$A$11:$A$16,0)),"")) | S41: =IF($E41="","",IFERROR(INDEX(단가설정!$D$11:$D$16,MATCH($E41,단가설정!$A$11:$A$16,0)),""))
A42: Y | B42: e) 에비뉴센터 별도 | C42: 에비뉴센터 | D42: SSL 인증서 갱신 + 서버 정비 | E42: 백엔드/CMS 개발 | G42: 300000 | H42: 500000 | I42: 500000 | M42: =IF($A42<>"Y",0,IF($J42<>"",$J42,IF($Q42="",$G42,ROUND($G42*(IF($E42="","",IFERROR(INDEX(단가설정!$B$11:$B$16,MATCH($E42,단가설정!$A$11:$A$16,0)),""))/$Q42),0)))) | N42: =IF($A42<>"Y",0,IF($K42<>"",$K42,IF($R42="",$H42,ROUND($H42*(IF($E42="","",IFERROR(INDEX(단가설정!$C$11:$C$16,MATCH($E42,단가설정!$A$11:$A$16,0)),""))/$R42),0)))) | O42: =IF($A42<>"Y",0,IF($L42<>"",$L42,IF($S42="",$I42,ROUND($I42*(IF($E42="","",IFERROR(INDEX(단가설정!$D$11:$D$16,MATCH($E42,단가설정!$A$11:$A$16,0)),""))/$S42),0)))) | Q42: =IF($E42="","",IFERROR(INDEX(단가설정!$B$11:$B$16,MATCH($E42,단가설정!$A$11:$A$16,0)),"")) | R42: =IF($E42="","",IFERROR(INDEX(단가설정!$C$11:$C$16,MATCH($E42,단가설정!$A$11:$A$16,0)),"")) | S42: =IF($E42="","",IFERROR(INDEX(단가설정!$D$11:$D$16,MATCH($E42,단가설정!$A$11:$A$16,0)),""))
A43: Y | B43: e) 에비뉴센터 별도 | C43: 에비뉴센터 | D43: 원페이지 랜딩 디자인 (PC+Mobile, 4섹션) | E43: UI 디자이너 | G43: 1500000 | H43: 2500000 | I43: 3500000 | M43: =IF($A43<>"Y",0,IF($J43<>"",$J43,IF($Q43="",$G43,ROUND($G43*(IF($E43="","",IFERROR(INDEX(단가설정!$B$11:$B$16,MATCH($E43,단가설정!$A$11:$A$16,0)),""))/$Q43),0)))) | N43: =IF($A43<>"Y",0,IF($K43<>"",$K43,IF($R43="",$H43,ROUND($H43*(IF($E43="","",IFERROR(INDEX(단가설정!$C$11:$C$16,MATCH($E43,단가설정!$A$11:$A$16,0)),""))/$R43),0)))) | O43: =IF($A43<>"Y",0,IF($L43<>"",$L43,IF($S43="",$I43,ROUND($I43*(IF($E43="","",IFERROR(INDEX(단가설정!$D$11:$D$16,MATCH($E43,단가설정!$A$11:$A$16,0)),""))/$S43),0)))) | Q43: =IF($E43="","",IFERROR(INDEX(단가설정!$B$11:$B$16,MATCH($E43,단가설정!$A$11:$A$16,0)),"")) | R43: =IF($E43="","",IFERROR(INDEX(단가설정!$C$11:$C$16,MATCH($E43,단가설정!$A$11:$A$16,0)),"")) | S43: =IF($E43="","",IFERROR(INDEX(단가설정!$D$11:$D$16,MATCH($E43,단가설정!$A$11:$A$16,0)),""))
...

Sheet 요약
A1: 견적 요약
A3: 구분 | B3: LOW | C3: MID | D3: HIGH | F3: 사용 방법
A4: a) 마스터 템플릿 | B4: =SUMIFS(견적입력!$M:$M,견적입력!$B:$B,$A4) | C4: =SUMIFS(견적입력!$N:$N,견적입력!$B:$B,$A4) | D4: =SUMIFS(견적입력!$O:$O,견적입력!$B:$B,$A4) | F4: 1. 단가설정 시트의 LOW/MID/HIGH 단가를 수정
A5: a-1) 브랜딩 리디자인 | B5: =SUMIFS(견적입력!$M:$M,견적입력!$B:$B,$A5) | C5: =SUMIFS(견적입력!$N:$N,견적입력!$B:$B,$A5) | D5: =SUMIFS(견적입력!$O:$O,견적입력!$B:$B,$A5) | F5: 2. 견적입력 시트에서 포함(Y/N)과 금액을 조정
A6: b) 브랜드 커스터마이징 | B6: =SUMIFS(견적입력!$M:$M,견적입력!$B:$B,$A6) | C6: =SUMIFS(견적입력!$N:$N,견적입력!$B:$B,$A6) | D6: =SUMIFS(견적입력!$O:$O,견적입력!$B:$B,$A6) | F6: 3. 요약 시트에서 최종 금액 확인
A7: c) 공통 기능 | B7: =SUMIFS(견적입력!$M:$M,견적입력!$B:$B,$A7) | C7: =SUMIFS(견적입력!$N:$N,견적입력!$B:$B,$A7) | D7: =SUMIFS(견적입력!$O:$O,견적입력!$B:$B,$A7)
A8: d) SEO/GEO 인프라 | B8: =SUMIFS(견적입력!$M:$M,견적입력!$B:$B,$A8) | C8: =SUMIFS(견적입력!$N:$N,견적입력!$B:$B,$A8) | D8: =SUMIFS(견적입력!$O:$O,견적입력!$B:$B,$A8)
A9: e) 에비뉴센터 별도 | B9: =SUMIFS(견적입력!$M:$M,견적입력!$B:$B,$A9) | C9: =SUMIFS(견적입력!$N:$N,견적입력!$B:$B,$A9) | D9: =SUMIFS(견적입력!$O:$O,견적입력!$B:$B,$A9)
A10: f) 기타 | B10: =SUMIFS(견적입력!$M:$M,견적입력!$B:$B,$A10) | C10: =SUMIFS(견적입력!$N:$N,견적입력!$B:$B,$A10) | D10: =SUMIFS(견적입력!$O:$O,견적입력!$B:$B,$A10)
A11: 합계 (VAT 별도) | B11: =SUM(B4:B10) | C11: =SUM(C4:C10) | D11: =SUM(D4:D10)
A12: VAT | B12: =B11*단가설정!$B$8 | C12: =C11*단가설정!$B$8 | D12: =D11*단가설정!$B$8
A13: VAT 포함 | B13: =B11+B12 | C13: =C11+C12 | D13: =D11+D12
A15: 선택 항목 수 | B15: =COUNTIF(견적입력!$A:$A,"Y")
A16: 제외 항목 수 | B16: =COUNTIF(견적입력!$A:$A,"N")
